<?xml version="1.0" encoding="utf-8"?>
<!-- This URDF was automatically created by SolidWorks to URDF Exporter! Originally created by Stephen Brawner (brawner@gmail.com) 
     Commit Version: 1.6.0-4-g7f85cfe  Build Version: 1.6.7995.38578
     For more information, please see http://wiki.ros.org/sw_urdf_exporter -->
<robot
  name="armurdf_standard_motor">
  <link
    name="base_link">
    <inertial>
      <origin
        xyz="0.06401797 0.00093364 0.06018482"
        rpy="0 0 0" />
      <mass
        value="1.19404" />
      <inertia
        ixx="0.00054518"
        ixy="-8.8651E-07"
        ixz="1.2762E-20"
        iyy="0.00099237"
        iyz="3.2702E-08"
        izz="0.0011813" />
    </inertial>
    <visual>
      <origin
        xyz="0 0 0"
        rpy="0 0 0" />
      <geometry>
        <mesh
          filename="package://armurdf_standard_motor/meshes/base_link.STL" />
      </geometry>
      <material
        name="">
        <color
          rgba="0.79216 0.81961 0.93333 1" />
      </material>
    </visual>
    <collision>
      <origin
        xyz="0 0 0"
        rpy="0 0 0" />
      <geometry>
        <mesh
          filename="package://armurdf_standard_motor/meshes/base_link.STL" />
      </geometry>
    </collision>
  </link>
  <link
    name="Link1">
    <inertial>
      <origin
        xyz="-0.00047343 0.28954791 0.0005662"
        rpy="0 0 0" />
      <mass
        value="0.54717" />
      <inertia
        ixx="0.0023759"
        ixy="3.3021E-06"
        ixz="-3.9537E-21"
        iyy="6.4486E-05"
        iyz="-5.53E-19"
        izz="0.0024336" />
    </inertial>
    <visual>
      <origin
        xyz="0 0 0"
        rpy="0 0 0" />
      <geometry>
        <mesh
          filename="package://armurdf_standard_motor/meshes/Link1.STL" />
      </geometry>
      <material
        name="">
        <color
          rgba="1 1 1 1" />
      </material>
    </visual>
    <collision>
      <origin
        xyz="0 0 0"
        rpy="0 0 0" />
      <geometry>
        <mesh
          filename="package://armurdf_standard_motor/meshes/Link1.STL" />
      </geometry>
    </collision>
  </link>
  <joint
    name="j1"
    type="revolute">
    <origin
      xyz="0 0 0.07"
      rpy="1.5708 0 1.57079265" />
    <parent
      link="base_link" />
    <child
      link="Link1" />
    <axis
      xyz="0 0 -1" />
    <limit
      lower="-1.57"
      upper="1.57"
      effort="30"
      velocity="3.14" />
  </joint>
  <link
    name="Link2">
    <inertial>
      <origin
        xyz="-0.0003464 0.2219719 0.00658453"
        rpy="0 0 0" />
      <mass
        value="0.5273" />
      <inertia
        ixx="0.00075992"
        ixy="1.0161E-06"
        ixz="4.134E-20"
        iyy="4.9865E-05"
        iyz="5.7918E-19"
        izz="0.00078302" />
    </inertial>
    <visual>
      <origin
        xyz="0 0 0"
        rpy="0 0 0" />
      <geometry>
        <mesh
          filename="package://armurdf_standard_motor/meshes/Link2.STL" />
      </geometry>
      <material
        name="">
        <color
          rgba="0.79216 0.81961 0.93333 0.25" />
      </material>
    </visual>
    <collision>
      <origin
        xyz="0 0 0"
        rpy="0 0 0" />
      <geometry>
        <mesh
          filename="package://armurdf_standard_motor/meshes/Link2.STL" />
      </geometry>
    </collision>
  </link>
  <joint
    name="j2"
    type="revolute">
    <origin
      xyz="-0.0005 0.35 0"
      rpy="0 0 0" />
    <parent
      link="Link1" />
    <child
      link="Link2" />
    <axis
      xyz="0 0 -1" />
    <limit
      lower="-2.32"
      upper="2.32"
      effort="10"
      velocity="3.14" />
  </joint>
  <link
    name="Link3">
    <inertial>
      <origin
        xyz="0.002693 0.11635 0.0019852"
        rpy="0 0 0" />
      <mass
        value="0.24563" />
      <inertia
        ixx="0.00013404"
        ixy="1.2628E-06"
        ixz="6.3612E-09"
        iyy="0.0001778"
        iyz="-1.8653E-10"
        izz="0.00013348" />
    </inertial>
    <visual>
      <origin
        xyz="0 0 0"
        rpy="0 0 0" />
      <geometry>
        <mesh
          filename="package://armurdf_standard_motor/meshes/Link3.STL" />
      </geometry>
      <material
        name="">
        <color
          rgba="0.79216 0.81961 0.93333 1" />
      </material>
    </visual>
    <collision>
      <origin
        xyz="0 0 0"
        rpy="0 0 0" />
      <geometry>
        <mesh
          filename="package://armurdf_standard_motor/meshes/Link3.STL" />
      </geometry>
    </collision>
  </link>
  <joint
    name="j3"
    type="revolute">
    <origin
      xyz="-0.000357142857063231 0.24999974489785 -0.00262500000000032"
      rpy="0 0 0" />
    <parent
      link="Link2" />
    <child
      link="Link3" />
    <axis
      xyz="0 0 -1" />
    <limit
      lower="-1.95"
      upper="1.95"
      effort="10"
      velocity="3.14" />
  </joint>
  <link
    name="tool_Link">
    <inertial>
      <origin
        xyz="0 0 0"
        rpy="0 0 0" />
      <mass
        value="0.0001" />
      <inertia
        ixx="1E-06"
        ixy="1E-06"
        ixz="0"
        iyy="1E-06"
        iyz="0"
        izz="0" />
    </inertial>
    <visual>
      <origin
        xyz="0 0 0"
        rpy="0 0 0" />
      <geometry>
        <mesh
          filename="package://armurdf_standard_motor/meshes/tool_Link.STL" />
      </geometry>
      <material
        name="">
        <color
          rgba="1 1 1 1" />
      </material>
    </visual>
    <collision>
      <origin
        xyz="0 0 0"
        rpy="0 0 0" />
      <geometry>
        <mesh
          filename="package://armurdf_standard_motor/meshes/tool_Link.STL" />
      </geometry>
    </collision>
  </link>
  <joint
    name="j_tool"
    type="fixed">
    <origin
      xyz="0.0034791 0.14696 -2.5E-05"
      rpy="0 0 0" />
    <parent
      link="Link3" />
    <child
      link="tool_Link" />
    <axis
      xyz="0 0 0" />
  </joint>
</robot>
